<?xml version="1.0" encoding="utf-8"?>
<!-- This URDF was automatically created by SolidWorks to URDF Exporter! Originally created by Stephen Brawner (brawner@gmail.com) 
     Commit Version: 1.6.0-4-g7f85cfe  Build Version: 1.6.7995.38578
     For more information, please see http://wiki.ros.org/sw_urdf_exporter -->
<robot
  name="puma">
  <link
    name="base_link">
    <inertial>
      <origin
        xyz="0.0084167 -0.0040666 -0.00054972"
        rpy="0 0 0" />
      <mass
        value="0.1218" />
      <inertia
        ixx="4.2685E-05"
        ixy="-6.9306E-23"
        ixz="2.4359E-21"
        iyy="5.7023E-05"
        iyz="2.418E-07"
        izz="3.3248E-05" />
    </inertial>
    <visual>
      <origin
        xyz="0 0 0"
        rpy="0 0 0" />
      <geometry>
        <mesh
          filename="package://puma/meshes/base_link.STL" />
      </geometry>
      <material
        name="">
        <color
          rgba="1 0.91373 0.24706 1" />
      </material>
    </visual>
    <collision>
      <origin
        xyz="0 0 0"
        rpy="0 0 0" />
      <geometry>
        <mesh
          filename="package://puma/meshes/base_link.STL" />
      </geometry>
    </collision>
  </link>
  <link
    name="Link1">
    <inertial>
      <origin
        xyz="-0.0012664 -3.4407E-05 0.047332"
        rpy="0 0 0" />
      <mass
        value="0.11358" />
      <inertia
        ixx="1.9493E-05"
        ixy="3.7239E-08"
        ixz="4.4045E-07"
        iyy="1.7784E-05"
        iyz="-4.487E-19"
        izz="2.3849E-05" />
    </inertial>
    <visual>
      <origin
        xyz="0 0 0"
        rpy="0 0 0" />
      <geometry>
        <mesh
          filename="package://puma/meshes/Link1.STL" />
      </geometry>
      <material
        name="">
        <color
          rgba="0.69804 0.69804 0.69804 1" />
      </material>
    </visual>
    <collision>
      <origin
        xyz="0 0 0"
        rpy="0 0 0" />
      <geometry>
        <mesh
          filename="package://puma/meshes/Link1.STL" />
      </geometry>
    </collision>
  </link>
  <joint
    name="Joint1"
    type="continuous">
    <origin
      xyz="-0.02 0 0"
      rpy="3.1416 0 -2.3041" />
    <parent
      link="base_link" />
    <child
      link="Link1" />
    <axis
      xyz="0 0 1" />
    <limit
      lower="-0.785"
      upper="0.785"
      effort="0"
      velocity="0" />
  </joint>
  <link
    name="Link2">
    <inertial>
      <origin
        xyz="-1.1519E-15 0.044669 -7.8627E-06"
        rpy="0 0 0" />
      <mass
        value="0.089477" />
      <inertia
        ixx="2.6927E-05"
        ixy="8.6821E-21"
        ixz="6.8324E-19"
        iyy="1.9359E-05"
        iyz="3.7239E-08"
        izz="1.3371E-05" />
    </inertial>
    <visual>
      <origin
        xyz="0 0 0"
        rpy="0 0 0" />
      <geometry>
        <mesh
          filename="package://puma/meshes/Link2.STL" />
      </geometry>
      <material
        name="">
        <color
          rgba="0.89804 0.91765 0.92941 1" />
      </material>
    </visual>
    <collision>
      <origin
        xyz="0 0 0"
        rpy="0 0 0" />
      <geometry>
        <mesh
          filename="package://puma/meshes/Link2.STL" />
      </geometry>
    </collision>
  </link>
  <joint
    name="Joint2"
    type="continuous">
    <origin
      xyz="0.01165 0 0.0635"
      rpy="1.5708 -1.4104 3.1416" />
    <parent
      link="Link1" />
    <child
      link="Link2" />
    <axis
      xyz="0 0 1" />
  </joint>
  <link
    name="Link3">
    <inertial>
      <origin
        xyz="0.030553 0.10452 -0.07322"
        rpy="0 0 0" />
      <mass
        value="0.092872" />
      <inertia
        ixx="2.761E-05"
        ixy="-6.0139E-19"
        ixz="-2.4458E-19"
        iyy="1.7178E-05"
        iyz="-1.1758E-07"
        izz="1.6478E-05" />
    </inertial>
    <visual>
      <origin
        xyz="0 0 0"
        rpy="0 0 0" />
      <geometry>
        <mesh
          filename="package://puma/meshes/Link3.STL" />
      </geometry>
      <material
        name="">
        <color
          rgba="0.89804 0.91765 0.92941 1" />
      </material>
    </visual>
    <collision>
      <origin
        xyz="0 0 0"
        rpy="0 0 0" />
      <geometry>
        <mesh
          filename="package://puma/meshes/Link3.STL" />
      </geometry>
    </collision>
  </link>
  <joint
    name="Joint3"
    type="continuous">
    <origin
      xyz="0 0 0.062678"
      rpy="0 0 0.50067" />
    <parent
      link="Link2" />
    <child
      link="Link3" />
    <axis
      xyz="0 0 1" />
  </joint>
  <link
    name="Link4">
    <inertial>
      <origin
        xyz="-1.8013E-14 0.015686 -0.037749"
        rpy="0 0 0" />
      <mass
        value="0.092872" />
      <inertia
        ixx="2.761E-05"
        ixy="9.455E-19"
        ixz="-1.2621E-19"
        iyy="1.7538E-05"
        iyz="-1.1758E-07"
        izz="1.6118E-05" />
    </inertial>
    <visual>
      <origin
        xyz="0 0 0"
        rpy="0 0 0" />
      <geometry>
        <mesh
          filename="package://puma/meshes/Link4.STL" />
      </geometry>
      <material
        name="">
        <color
          rgba="0.89804 0.91765 0.92941 1" />
      </material>
    </visual>
    <collision>
      <origin
        xyz="0 0 0"
        rpy="0 0 0" />
      <geometry>
        <mesh
          filename="package://puma/meshes/Link4.STL" />
      </geometry>
    </collision>
  </link>
  <joint
    name="Joint4"
    type="continuous">
    <origin
      xyz="0.030553 0.12727 -0.088328"
      rpy="-1.5708 0.016547 3.1416" />
    <parent
      link="Link3" />
    <child
      link="Link4" />
    <axis
      xyz="0 0 1" />
  </joint>
  <link
    name="Link5">
    <inertial>
      <origin
        xyz="3.6832E-14 0.048595 -0.018266"
        rpy="0 0 0" />
      <mass
        value="0.092872" />
      <inertia
        ixx="2.761E-05"
        ixy="-8.1178E-19"
        ixz="3.7449E-19"
        iyy="1.7178E-05"
        iyz="-1.9206E-07"
        izz="1.6478E-05" />
    </inertial>
    <visual>
      <origin
        xyz="0 0 0"
        rpy="0 0 0" />
      <geometry>
        <mesh
          filename="package://puma/meshes/Link5.STL" />
      </geometry>
      <material
        name="">
        <color
          rgba="0.89804 0.91765 0.92941 1" />
      </material>
    </visual>
    <collision>
      <origin
        xyz="0 0 0"
        rpy="0 0 0" />
      <geometry>
        <mesh
          filename="package://puma/meshes/Link5.STL" />
      </geometry>
    </collision>
  </link>
  <joint
    name="Joint5"
    type="continuous">
    <origin
      xyz="0 0 -0.06222"
      rpy="-1.5708 -0.16951 -3.1416" />
    <parent
      link="Link4" />
    <child
      link="Link5" />
    <axis
      xyz="0 0 1" />
  </joint>
  <link
    name="Link6">
    <inertial>
      <origin
        xyz="5.7315E-15 0.012025 -0.00465"
        rpy="0 0 0" />
      <mass
        value="0.016021" />
      <inertia
        ixx="6.138E-06"
        ixy="-6.1939E-21"
        ixz="8.9997E-21"
        iyy="5.3342E-06"
        iyz="2.4882E-21"
        izz="1.8104E-06" />
    </inertial>
    <visual>
      <origin
        xyz="0 0 0"
        rpy="0 0 0" />
      <geometry>
        <mesh
          filename="package://puma/meshes/Link6.STL" />
      </geometry>
      <material
        name="">
        <color
          rgba="0.89804 0.91765 0.92941 1" />
      </material>
    </visual>
    <collision>
      <origin
        xyz="0 0 0"
        rpy="0 0 0" />
      <geometry>
        <mesh
          filename="package://puma/meshes/Link6.STL" />
      </geometry>
    </collision>
  </link>
  <joint
    name="Joint6"
    type="continuous">
    <origin
      xyz="0 0.05255 -0.03165"
      rpy="1.5708 1.4408 0" />
    <parent
      link="Link5" />
    <child
      link="Link6" />
    <axis
      xyz="0 0 1" />
  </joint>
</robot>