<?xml version="1.0" encoding="utf-8"?>
<!-- This URDF was automatically created by SolidWorks to URDF Exporter! Originally created by Stephen Brawner (brawner@gmail.com) 
     Commit Version: 1.6.0-4-g7f85cfe  Build Version: 1.6.7995.38578
     For more information, please see http://wiki.ros.org/sw_urdf_exporter -->
<robot
  name="Robot">
  <link
    name="base_link">
    <inertial>
      <origin
        xyz="5.51829554129647E-12 -1.92333779897319E-11 0.110518251024487"
        rpy="0 0 0" />
      <mass
        value="0.624741189613739" />
      <inertia
        ixx="0.00264900661497622"
        ixy="-4.77894812235539E-15"
        ixz="-8.33462393002094E-14"
        iyy="0.00264903402219447"
        iyz="1.27464432797341E-13"
        izz="0.000280021902306363" />
    </inertial>
    <visual>
      <origin
        xyz="0 0 0"
        rpy="0 0 0" />
      <geometry>
        <mesh
          filename="package://rviz2_shape/meshes/base_link.STL" />
      </geometry>
      <material
        name="">
        <color
          rgba="1 1 1 1" />
      </material>
    </visual>
    <collision>
      <origin
        xyz="0 0 0"
        rpy="0 0 0" />
      <geometry>
        <mesh
          filename="package://rviz2_shape/meshes/base_link.STL" />
      </geometry>
    </collision>
  </link>
  <link
    name="Link1">
    <inertial>
      <origin
        xyz="-2.10426603802187E-18 -4.16333634234434E-17 -2.77555756156289E-17"
        rpy="0 0 0" />
      <mass
        value="0.000467327412287183" />
      <inertia
        ixx="5.73611761707357E-09"
        ixy="-2.98012138337077E-26"
        ixz="6.52250449855772E-26"
        iyy="5.73611761707357E-09"
        iyz="2.68833699079734E-24"
        izz="9.67358040957279E-09" />
    </inertial>
    <visual>
      <origin
        xyz="0 0 0"
        rpy="0 0 0" />
      <geometry>
        <mesh
          filename="package://rviz2_shape/meshes/Link1.STL" />
      </geometry>
      <material
        name="">
        <color
          rgba="1 1 1 1" />
      </material>
    </visual>
    <collision>
      <origin
        xyz="0 0 0"
        rpy="0 0 0" />
      <geometry>
        <mesh
          filename="package://rviz2_shape/meshes/Link1.STL" />
      </geometry>
    </collision>
  </link>
  <joint
    name="joint1"
    type="revolute">
    <origin
      xyz="0 -0.2435 0"
      rpy="1.1711 0 0" />
    <parent
      link="base_link" />
    <child
      link="Link1" />
    <axis
      xyz="1 0 0" />
    <limit
      lower="-1"
      upper="1"
      effort="0"
      velocity="10" />
  </joint>
  <link
    name="Link2">
    <inertial>
      <origin
        xyz="3.20287685262599E-11 -0.133500000031401 3.25114796195791E-11"
        rpy="0 0 0" />
      <mass
        value="0.62744703308605" />
      <inertia
        ixx="0.00264920679100832"
        ixy="1.35607210139874E-13"
        ixz="-2.57275754519948E-15"
        iyy="0.00028012789917579"
        iyz="-1.86840397754101E-13"
        izz="0.00264920679100226" />
    </inertial>
    <visual>
      <origin
        xyz="0 0 0"
        rpy="0 0 0" />
      <geometry>
        <mesh
          filename="package://rviz2_shape/meshes/Link2.STL" />
      </geometry>
      <material
        name="">
        <color
          rgba="1 1 1 1" />
      </material>
    </visual>
    <collision>
      <origin
        xyz="0 0 0"
        rpy="0 0 0" />
      <geometry>
        <mesh
          filename="package://rviz2_shape/meshes/Link2.STL" />
      </geometry>
    </collision>
  </link>
  <joint
    name="joint2"
    type="revolute">
    <origin
      xyz="0 0 0"
      rpy="-2.0956 0 -1.5708" />
    <parent
      link="Link1" />
    <child
      link="Link2" />
    <axis
      xyz="1 0 0" />
    <limit
      lower="-1"
      upper="1"
      effort="10"
      velocity="10" />
  </joint>
</robot>