<?xml version="1.0" encoding="utf-8"?>
<!-- This URDF was automatically created by SolidWorks to URDF Exporter! Originally created by Stephen Brawner (brawner@gmail.com) 
     Commit Version: 1.6.0-4-g7f85cfe  Build Version: 1.6.7995.38578
     For more information, please see http://wiki.ros.org/sw_urdf_exporter -->
<robot
  name="myrobot">
  <link
    name="base_link">
    <inertial>
      <origin
        xyz="0.0084167 0.00054972 -0.0040666"
        rpy="0 0 0" />
      <mass
        value="0.1218" />
      <inertia
        ixx="4.2685E-05"
        ixy="-1.9391E-21"
        ixz="-5.6265E-24"
        iyy="3.3248E-05"
        iyz="-2.418E-07"
        izz="5.7023E-05" />
    </inertial>
    <visual>
      <origin
        xyz="0 0 0"
        rpy="0 0 0" />
      <geometry>
        <mesh
          filename="package://myrobot/meshes/base_link.STL" />
      </geometry>
      <material
        name="">
        <color
          rgba="1 0.91373 0.24706 1" />
      </material>
    </visual>
    <collision>
      <origin
        xyz="0 0 0"
        rpy="0 0 0" />
      <geometry>
        <mesh
          filename="package://myrobot/meshes/Link0.STL" />
      </geometry>
    </collision>
  </link>
  <link
    name="Link1">
    <inertial>
      <origin
        xyz="-0.030517 3.4407E-05 0.053377"
        rpy="0 0 0" />
      <mass
        value="0.11358" />
      <inertia
        ixx="2.5955E-05"
        ixy="7.356E-19"
        ixz="4.4045E-07"
        iyy="1.7784E-05"
        iyz="-3.7239E-08"
        izz="1.7387E-05" />
    </inertial>
    <visual>
      <origin
        xyz="0 0 0"
        rpy="0 0 0" />
      <geometry>
        <mesh
          filename="package://myrobot/meshes/Link1.STL" />
      </geometry>
      <material
        name="">
        <color
          rgba="0.69804 0.69804 0.69804 1" />
      </material>
    </visual>
    <collision>
      <origin
        xyz="0 0 0"
        rpy="0 0 0" />
      <geometry>
        <mesh
          filename="package://myrobot/meshes/Link1.STL" />
      </geometry>
    </collision>
  </link>
  <joint
    name="Joint0"
    type="continuous">
    <origin
      xyz="-0.02 0 0"
      rpy="-3.1416 0 -0.0057662" />
    <parent
      link="base_link" />
    <child
      link="Link1" />
    <axis
      xyz="0 0 1" />
  </joint>
  <link
    name="Link2">
    <inertial>
      <origin
        xyz="6.9389E-17 0.044669 -7.8627E-06"
        rpy="0 0 0" />
      <mass
        value="0.089477" />
      <inertia
        ixx="2.6927E-05"
        ixy="1.2866E-21"
        ixz="1.5751E-18"
        iyy="1.9359E-05"
        iyz="3.7239E-08"
        izz="1.3371E-05" />
    </inertial>
    <visual>
      <origin
        xyz="0 0 0"
        rpy="0 0 0" />
      <geometry>
        <mesh
          filename="package://myrobot/meshes/Link2.STL" />
      </geometry>
      <material
        name="">
        <color
          rgba="0.89804 0.91765 0.92941 1" />
      </material>
    </visual>
    <collision>
      <origin
        xyz="0 0 0"
        rpy="0 0 0" />
      <geometry>
        <mesh
          filename="package://myrobot/meshes/Link2.STL" />
      </geometry>
    </collision>
  </link>
  <joint
    name="Joint1"
    type="continuous">
    <origin
      xyz="-0.0465000000000003 0 0.0836499999999999"
      rpy="1.57079632679489 -1.13894515984459 0" />
    <parent
      link="Link1" />
    <child
      link="Link2" />
    <axis
      xyz="0 0 1" />
  </joint>
  <link
    name="Link3">
    <inertial>
      <origin
        xyz="0.015065 0.047481 0.0003083"
        rpy="0 0 0" />
      <mass
        value="0.092872" />
      <inertia
        ixx="2.0796E-05"
        ixy="-2.2101E-07"
        ixz="-1.2744E-09"
        iyy="1.7188E-05"
        iyz="-3.5145E-08"
        izz="2.3282E-05" />
    </inertial>
    <visual>
      <origin
        xyz="0 0 0"
        rpy="0 0 0" />
      <geometry>
        <mesh
          filename="package://myrobot/meshes/Link3.STL" />
      </geometry>
      <material
        name="">
        <color
          rgba="0.89804 0.91765 0.92941 1" />
      </material>
    </visual>
    <collision>
      <origin
        xyz="0 0 0"
        rpy="0 0 0" />
      <geometry>
        <mesh
          filename="package://myrobot/meshes/Link3.STL" />
      </geometry>
    </collision>
  </link>
  <joint
    name="Joint2"
    type="continuous">
    <origin
      xyz="0 0.06365 0"
      rpy="-0.0057662 0 0.43185" />
    <parent
      link="Link2" />
    <child
      link="Link3" />
    <axis
      xyz="0 0 1" />
  </joint>
  <link
    name="Link4">
    <inertial>
      <origin
        xyz="-5.8271E-14 0.015686 -0.081731"
        rpy="0 0 0" />
      <mass
        value="0.092872" />
      <inertia
        ixx="2.761E-05"
        ixy="1.899E-18"
        ixz="-1.1832E-18"
        iyy="1.7538E-05"
        iyz="-1.1758E-07"
        izz="1.6118E-05" />
    </inertial>
    <visual>
      <origin
        xyz="0 0 0"
        rpy="0 0 0" />
      <geometry>
        <mesh
          filename="package://myrobot/meshes/Link4.STL" />
      </geometry>
      <material
        name="">
        <color
          rgba="0.89804 0.91765 0.92941 1" />
      </material>
    </visual>
    <collision>
      <origin
        xyz="0 0 0"
        rpy="0 0 0" />
      <geometry>
        <mesh
          filename="package://myrobot/meshes/Link4.STL" />
      </geometry>
    </collision>
  </link>
  <joint
    name="Joint3"
    type="continuous">
    <origin
      xyz="0.028096 0.024938 0.0001438"
      rpy="1.7275 1.534 0.063322" />
    <parent
      link="Link3" />
    <child
      link="Link4" />
    <axis
      xyz="0 0 1" />
  </joint>
  <link
    name="Link5">
    <inertial>
      <origin
        xyz="1.0422E-14 0.048595 -0.018266"
        rpy="0 0 0" />
      <mass
        value="0.092872" />
      <inertia
        ixx="2.761E-05"
        ixy="3.8498E-19"
        ixz="1.2532E-18"
        iyy="1.7178E-05"
        iyz="-1.9206E-07"
        izz="1.6478E-05" />
    </inertial>
    <visual>
      <origin
        xyz="0 0 0"
        rpy="0 0 0" />
      <geometry>
        <mesh
          filename="package://myrobot/meshes/Link5.STL" />
      </geometry>
      <material
        name="">
        <color
          rgba="0.89804 0.91765 0.92941 1" />
      </material>
    </visual>
    <collision>
      <origin
        xyz="0 0 0"
        rpy="0 0 0" />
      <geometry>
        <mesh
          filename="package://myrobot/meshes/Link5.STL" />
      </geometry>
    </collision>
  </link>
  <joint
    name="Joint4"
    type="continuous">
    <origin
      xyz="0 0 -0.106202496734865"
      rpy="-1.5707963267949 0.247093949073706 -3.14159265358959" />
    <parent
      link="Link4" />
    <child
      link="Link5" />
    <axis
      xyz="0 0 1" />
  </joint>
  <link
    name="Link6">
    <inertial>
      <origin
        xyz="2.4258E-14 0.012025 0.025207"
        rpy="0 0 0" />
      <mass
        value="0.016021" />
      <inertia
        ixx="6.138E-06"
        ixy="-8.8674E-22"
        ixz="-6.5281E-21"
        iyy="5.3342E-06"
        iyz="-2.5146E-21"
        izz="1.8104E-06" />
    </inertial>
    <visual>
      <origin
        xyz="0 0 0"
        rpy="0 0 0" />
      <geometry>
        <mesh
          filename="package://myrobot/meshes/Link6.STL" />
      </geometry>
      <material
        name="">
        <color
          rgba="0.89804 0.91765 0.92941 1" />
      </material>
    </visual>
    <collision>
      <origin
        xyz="0 0 0"
        rpy="0 0 0" />
      <geometry>
        <mesh
          filename="package://myrobot/meshes/Link6.STL" />
      </geometry>
    </collision>
  </link>
  <joint
    name="Joint5"
    type="continuous">
    <origin
      xyz="0 0.0319927225582785 -0.0316499999999904"
      rpy="1.57079632679486 1.50652247400493 3.14159265358979" />
    <parent
      link="Link5" />
    <child
      link="Link6" />
    <axis
      xyz="0 0 1" />
  </joint>
</robot>