<?xml version="1.0" encoding="utf-8"?>
<!-- This URDF was automatically created by SolidWorks to URDF Exporter! Originally created by Stephen Brawner (brawner@gmail.com) 
     Commit Version: 1.6.0-4-g7f85cfe  Build Version: 1.6.7995.38578
     For more information, please see http://wiki.ros.org/sw_urdf_exporter -->
<robot
  name="hyper_robot4">
  <link
    name="base_link">
    <inertial>
      <origin
        xyz="-0.00080332 -0.0073137 -0.027846"
        rpy="0 0 0" />
      <mass
        value="1.4" />
      <inertia
        ixx="0.0017764"
        ixy="-3.447E-06"
        ixz="2.1856E-07"
        iyy="0.0019607"
        iyz="2.7013E-07"
        izz="0.0032525" />
    </inertial>
    <visual>
      <origin
        xyz="0 0 0"
        rpy="0 0 0" />
      <geometry>
        <mesh
          filename="package://hyper_robot4/meshes/base_link.STL" />
      </geometry>
      <material
        name="">
        <color
          rgba="1 1 1 1" />
      </material>
    </visual>
    <collision>
      <!-- <origin
        xyz="0 0 0"
        rpy="0 0 0" />
      <geometry>
        <mesh
          filename="package://hyper_robot4/meshes/base_link.STL" />
      </geometry> -->
      <origin xyz="0 0 -0.1" rpy="0 0 0" />
        <geometry>
          <box size="0.4 0.4 0.2" />
        </geometry>
    </collision>
    <surface>
      <contact>
        <ode>
          <min_depth>0.001</min_depth>
          <max_vel>0</max_vel>
        </ode>
      </contact>
      <friction>
        <ode>0.5</ode>
      </friction>
    </surface>
  </link>
  <link
    name="Link1">
    <inertial>
      <origin
        xyz="0.03091 3.5089E-05 0.029993"
        rpy="0 0 0" />
      <mass
        value="0.11138" />
      <inertia
        ixx="2.6005E-05"
        ixy="-2.14E-13"
        ixz="2.8039E-07"
        iyy="1.7177E-05"
        iyz="3.7239E-08"
        izz="1.71E-05" />
    </inertial>
    <visual>
      <origin
        xyz="0 0 0"
        rpy="0 0 0" />
      <geometry>
        <mesh
          filename="package://hyper_robot4/meshes/Link1.STL" />
      </geometry>
      <material
        name="">
        <color
          rgba="0.69804 0.69804 0.69804 1" />
      </material>
    </visual>
    <!-- <collision>
      <origin
        xyz="0 0 0"
        rpy="0 0 0" />
      <geometry>
        <mesh
          filename="package://hyper_robot4/meshes/Link1.STL" />
      </geometry>
    </collision> -->
  </link>
  <joint
    name="Joint0"
    type="revolute">
    <origin
      xyz="0.0200000000000003 0 -0.18065"
      rpy="0 0 0" />
    <parent
      link="base_link" />
    <child
      link="Link1" />
    <axis
      xyz="0 0 1" />
    <limit
      lower="-1.5707"
      upper="1.5707"
      effort="1"
      velocity="1" />
    <dynamics damping="0.01" friction="0.01"/>
  </joint>
  <link
    name="Link2">
    <inertial>
      <origin
        xyz="0.044669 -3.9552E-15 -7.8627E-06"
        rpy="0 0 0" />
      <mass
        value="0.089477" />
      <inertia
        ixx="1.9359E-05"
        ixy="3.3333E-19"
        ixz="3.7239E-08"
        iyy="2.6927E-05"
        iyz="3.7967E-21"
        izz="1.3371E-05" />
    </inertial>
    <visual>
      <origin
        xyz="0 0 0"
        rpy="0 0 0" />
      <geometry>
        <mesh
          filename="package://hyper_robot4/meshes/Link2.STL" />
      </geometry>
      <material
        name="">
        <color
          rgba="0.89804 0.91765 0.92941 1" />
      </material>
    </visual>
    <!-- <collision>
      <origin
        xyz="0 0 0"
        rpy="0 0 0" />
      <geometry>
        <mesh
          filename="package://hyper_robot4/meshes/Link2.STL" />
      </geometry>
    </collision> -->
  </link>
  <joint
    name="Joint1"
    type="revolute">
    <origin
      xyz="0.0465 0 0"
      rpy="1.5707963267949 1.5707963267949 0" />
    <parent
      link="Link1" />
    <child
      link="Link2" />
    <axis
      xyz="0 0 1" />
    <limit
      lower="-1.5707"
      upper="1.5707"
      effort="1"
      velocity="1" />
    <dynamics damping="0.01" friction="0.01"/>
  </joint>
  <link
    name="Link3">
    <inertial>
      <origin
        xyz="-0.0027639 0.053128 3.399E-05"
        rpy="0 0 0" />
      <mass
        value="0.09428" />
      <inertia
        ixx="2.1264E-05"
        ixy="4.9299E-07"
        ixz="3.2007E-18"
        iyy="1.7761E-05"
        iyz="-5.2408E-19"
        izz="2.4231E-05" />
    </inertial>
    <visual>
      <origin
        xyz="0 0 0"
        rpy="0 0 0" />
      <geometry>
        <mesh
          filename="package://hyper_robot4/meshes/Link3.STL" />
      </geometry>
      <material
        name="">
        <color
          rgba="0.89804 0.91765 0.92941 1" />
      </material>
    </visual>
    <!-- <collision>
      <origin
        xyz="0 0 0"
        rpy="0 0 0" />
      <geometry>
        <mesh
          filename="package://hyper_robot4/meshes/Link3.STL" />
      </geometry>
    </collision> -->
  </link>
  <joint
    name="Joint2"
    type="revolute">
    <origin
      xyz="0.0636500000000007 0 0"
      rpy="0 0 -1.5707963267949" />
    <parent
      link="Link2" />
    <child
      link="Link3" />
    <axis
      xyz="0 0 -1" />
    <limit
      lower="-1.5707"
      upper="1.5707"
      effort="1"
      velocity="1" />
    <dynamics damping="0.01" friction="0.01"/>
  </joint>
  <link
    name="Link4">
    <inertial>
      <origin
        xyz="2.867E-14 0.0031256 -0.024086"
        rpy="0 0 0" />
      <mass
        value="0.09428" />
      <inertia
        ixx="2.8558E-05"
        ixy="-5.4321E-20"
        ixz="1.1994E-18"
        iyy="1.7996E-05"
        iyz="4.1851E-07"
        izz="1.6701E-05" />
    </inertial>
    <visual>
      <origin
        xyz="0 0 0"
        rpy="0 0 0" />
      <geometry>
        <mesh
          filename="package://hyper_robot4/meshes/Link4.STL" />
      </geometry>
      <material
        name="">
        <color
          rgba="0.89804 0.91765 0.92941 1" />
      </material>
    </visual>
    <!-- <collision>
      <origin
        xyz="0 0 0"
        rpy="0 0 0" />
      <geometry>
        <mesh
          filename="package://hyper_robot4/meshes/Link4.STL" />
      </geometry>
    </collision> -->
  </link>
  <joint
    name="Joint3"
    type="revolute">
    <origin
      xyz="0.00965 0.13565 0"
      rpy="-1.5708 -1.5708 0" />
    <parent
      link="Link3" />
    <child
      link="Link4" />
    <axis
      xyz="0 0 1" />
    <limit
      lower="-1.5707"
      upper="1.5707"
      effort="1"
      velocity="1" />
    <dynamics damping="0.01" friction="0.01"/>
  </joint>
  <link
    name="Link5">
    <inertial>
      <origin
        xyz="-9.7548E-14 0.044044 8.1785E-05"
        rpy="0 0 0" />
      <mass
        value="0.039183" />
      <inertia
        ixx="2.725E-05"
        ixy="4.2357E-17"
        ixz="-4.6187E-18"
        iyy="8.1409E-06"
        iyz="3.294E-18"
        izz="2.2451E-05" />
    </inertial>
    <visual>
      <origin
        xyz="0 0 0"
        rpy="0 0 0" />
      <geometry>
        <mesh
          filename="package://hyper_robot4/meshes/Link5.STL" />
      </geometry>
      <material
        name="">
        <color
          rgba="0.89804 0.91765 0.92941 1" />
      </material>
    </visual>
    <!-- <collision>
      <origin
        xyz="0 0 0"
        rpy="0 0 0" />
      <geometry>
        <mesh
          filename="package://hyper_robot4/meshes/Link5.STL" />
      </geometry>
    </collision> -->
  </link>
  <joint
    name="Joint4"
    type="revolute">
    <origin
      xyz="0 0 0"
      rpy="1.5708 0 0" />
    <parent
      link="Link4" />
    <child
      link="Link5" />
    <axis
      xyz="0 0 1" />
    <limit
      lower="-1.5707"
      upper="1.5707"
      effort="1"
      velocity="1" />
    <dynamics damping="0.01" friction="0.01"/>
  </joint>
  <link
    name="Link6">
    <inertial>
      <origin
        xyz="-2.6202E-08 -2.259E-08 -0.067545"
        rpy="0 0 0" />
      <mass
        value="0.0096839" />
      <inertia
        ixx="1.0979E-05"
        ixy="-1.7005E-13"
        ixz="1.5693E-11"
        iyy="1.0979E-05"
        iyz="1.3536E-11"
        izz="1.0733E-07" />
    </inertial>
    <visual>
      <origin
        xyz="0 0 0"
        rpy="0 0 0" />
      <geometry>
        <mesh
          filename="package://hyper_robot4/meshes/Link6.STL" />
      </geometry>
      <material
        name="">
        <color
          rgba="0.69804 0.69804 0.69804 1" />
      </material>
    </visual>
    <!-- <collision>
      <origin
        xyz="0 0 0"
        rpy="0 0 0" />
      <geometry>
        <mesh
          filename="package://hyper_robot4/meshes/Link6.STL" />
      </geometry>
    </collision> -->
  </link>
  <joint
    name="Joint5"
    type="fixed">
    <origin
      xyz="0 0.177384929880473 0"
      rpy="-1.57079632679532 0 0" />
    <parent
      link="Link5" />
    <child
      link="Link6" />
    <axis
      xyz="0 0 1" />
    <limit
      lower="-1.5707"
      upper="1.5707"
      effort="1"
      velocity="1" />
  </joint>
  <!-- <transmission name="joint5_trans">
    <type>transmission_interface/SimpleTransmission</type>
    <joint name="Joint5">
      <hardwareInterface>EffortJointInterface</hardwareInterface>
    </joint>
    <actuator name="joint5_motor">
      <mechanicalReduction>1</mechanicalReduction>
      <hardwareInterface>EffortJointInterface</hardwareInterface>
    </actuator>
  </transmission> -->
  <link name="freedom_roll" />
  <joint
    name="JointPenRoll"
    type="revolute">
    <parent
      link="Link6" />
    <child
      link="freedom_roll"/>
    <axis
      xyz="1 0 0"/>
    <limit
      lower="-0.7854"
      upper="0.7854"
      effort="1"
      velocity="1" />
  </joint>
  <link name="free_endeffector" />
  <joint
    name="JointPenPitch"
    type="revolute">
    <parent
      link="freedom_roll" />
    <child
      link="free_endeffector"/>
    <axis
      xyz="0 1 0"/>
    <limit
      lower="-0.7854"
      upper="0.7854"
      effort="1"
      velocity="1" />
  </joint>
  <link
    name="/imu_link">
    <inertial>
      <origin
        xyz="0 0 0"
        rpy="0 0 0" />
      <mass
        value="0.015" />
      <inertia
        ixx="1E-05"
        ixy="0"
        ixz="0"
        iyy="0"
        iyz="0"
        izz="0" />
    </inertial>
    <visual>
      <origin xyz="0 0 0" rpy="0 0 0" />
        <geometry>
          <box size="0.01 0.01 0.01" />
        </geometry>
        <material name="red">
          <color rgba="1 0 0 1" />
        </material>
      </visual>
  </link>
  <link name="imu_middle"/>
  <joint
    name="/imu_prismatic"
    type="prismatic">
    <origin
      xyz="0 0 0"
      rpy="0 0 0" />
    <parent
      link="base_link" />
    <child
      link="imu_middle" />
    <axis
      xyz="0 0 1" />
    <limit
      lower="-0.01"
      upper="0.01"
      effort="0"
      velocity="0" />
    <dynamics damping="0.01" friction="0" spring_reference="0" spring_stiffness="1000"/>
    <use_parent_model_frame>1</use_parent_model_frame>
  </joint>
  <joint
    name="/imu_joint"
    type="revolute">
    <origin
      xyz="0 0 0.02"
      rpy="0 0 0" />
    <parent
      link="base_link" />
    <child
      link="/imu_link" />
    <axis
      xyz="0 0 1" />
    <limit
      lower="0"
      upper="0"
      effort="0"
      velocity="0" />
    <dynamics damping="0.01" friction="0" spring_reference="0" spring_stiffness="1000"/>
    <use_parent_model_frame>1</use_parent_model_frame>
  </joint>
  <!-- rotor -->
  <link
    name="rotor_0">
    <inertial>
      <origin
        xyz="1.9715E-13 -0.0044832 -3.5041E-14"
        rpy="-1.5708 0 1.7863" />
      <mass
        value="0.022944" />
      <inertia
        ixx="8.117E-07"
        ixy="-1.5304E-17"
        ixz="2.5395E-06"
        iyy="9.7213E-05"
        iyz="2.8509E-18"
        izz="9.6561E-05" />
    </inertial>
    <visual>
      <origin
        xyz="0 0 0"
        rpy="-1.5708 0 1.7863" />
      <geometry>
        <mesh
          filename="package://hyper_robot4/meshes/rotor0.STL" />
      </geometry>
      <material
        name="">
        <color
          rgba="1 1 1 1" />
      </material>
    </visual>
    <!-- <collision>
      <origin
        xyz="0 0 0"
        rpy="0 0 0" />
      <geometry>
        <mesh
          filename="package://hyper_robot5/meshes/rotor0.STL" />
      </geometry>
    </collision> -->
  </link>
  <joint
    name="rotor_0_joint"
    type="continuous">
    <origin
      xyz="0.15778 -0.15778 0.022914"
      rpy="0 0 0" />
    <parent
      link="base_link" />
    <child
      link="rotor_0" />
    <axis
      xyz="0 0 1" />
  </joint>
  <link
    name="rotor_1">
    <inertial>
      <origin
        xyz="-7.7446E-10 -0.0044832 2.7986E-10"
        rpy="-1.5708 0 1.7179" />
      <mass
        value="0.022944" />
      <inertia
        ixx="8.1171E-07"
        ixy="4.1874E-14"
        ixz="2.5395E-06"
        iyy="9.7213E-05"
        iyz="-1.6511E-14"
        izz="9.6562E-05" />
    </inertial>
    <visual>
      <origin
        xyz="0 0 0"
        rpy="-1.5708 0 1.7179" />
      <geometry>
        <mesh
          filename="package://hyper_robot4/meshes/rotor1.STL" />
      </geometry>
      <material
        name="">
        <color
          rgba="1 1 1 1" />
      </material>
    </visual>
    <!-- <collision>
      <origin
        xyz="0 0 0"
        rpy="0 0 0" />
      <geometry>
        <mesh
          filename="package://hyper_robot5/meshes/rotor1.STL" />
      </geometry>
    </collision> -->
  </link>
  <joint
    name="rotor_1_joint"
    type="continuous">
    <origin
      xyz="-0.15778 0.15778 0.022914"
      rpy="0 0 0" />
    <parent
      link="base_link" />
    <child
      link="rotor_1" />
    <axis
      xyz="0 0 1" />
  </joint>
  <link
    name="rotor_2">
    <inertial>
      <origin
        xyz="2.4821E-09 0.0060996 3.4129E-10"
        rpy="1.5708 0 0.18169" />
      <mass
        value="0.022896" />
      <inertia
        ixx="8.0904E-07"
        ixy="5.4318E-14"
        ixz="-2.5351E-06"
        iyy="9.711E-05"
        iyz="2.2555E-14"
        izz="9.646E-05" />
    </inertial>
    <visual>
      <origin
        xyz="0 0 0"
        rpy="1.5708 0 0.18169" />
      <geometry>
        <mesh
          filename="package://hyper_robot4/meshes/rotor2.STL" />
      </geometry>
      <material
        name="">
        <color
          rgba="1 1 1 1" />
      </material>
    </visual>
    <!-- <collision>
      <origin
        xyz="0 0 0"
        rpy="0 0 0" />
      <geometry>
        <mesh
          filename="package://hyper_robot5/meshes/rotor2.STL" />
      </geometry>
    </collision> -->
  </link>
  <joint
    name="rotor_2_joint"
    type="continuous">
    <origin
      xyz="0.15778 0.15778 0.0245"
      rpy="0 0 0" />
    <parent
      link="base_link" />
    <child
      link="rotor_2" />
    <axis
      xyz="0 0 1" />
  </joint>
  <link
    name="rotor_3">
    <inertial>
      <origin
        xyz="1.4557E-08 -0.0045503 2.7709E-09"
        rpy="-1.5708 0 -2.9802" />
      <mass
        value="0.022896" />
      <inertia
        ixx="8.0904E-07"
        ixy="6.176E-13"
        ixz="-2.5351E-06"
        iyy="9.7111E-05"
        iyz="6.4653E-14"
        izz="9.6461E-05" />
    </inertial>
    <visual>
      <origin
        xyz="0 0 0"
        rpy="-1.5708 0 -2.9802" />
      <geometry>
        <mesh
          filename="package://hyper_robot4/meshes/rotor3.STL" />
      </geometry>
      <material
        name="">
        <color
          rgba="1 1 1 1" />
      </material>
    </visual>
    <!-- <collision>
      <origin
        xyz="0 0 0"
        rpy="0 0 0" />
      <geometry>
        <mesh
          filename="package://hyper_robot5/meshes/rotor3.STL" />
      </geometry>
    </collision> -->
  </link>
  <joint
    name="rotor_3_joint"
    type="continuous">
    <origin
      xyz="-0.15778 -0.15778 0.02285"
      rpy="0 0 0" />
    <parent
      link="base_link" />
    <child
      link="rotor_3" />
    <axis
      xyz="0 0 1" />
  </joint>
  <!-- Gazebo Plugin -->
  <gazebo>
    <plugin name='rosbag' filename='libgazebo_multirotor_base_plugin.so'>
        <robotNamespace/>
        <linkName>base_link</linkName>
        <rotorVelocitySlowdownSim>10</rotorVelocitySlowdownSim>
      </plugin>
      <plugin name='front_right_motor_model' filename='libgazebo_motor_model.so'>
        <robotNamespace/>
        <jointName>rotor_0_joint</jointName>
        <linkName>rotor_0</linkName>
        <turningDirection>ccw</turningDirection>
        <timeConstantUp>0.0125</timeConstantUp>
        <timeConstantDown>0.025</timeConstantDown>
        <maxRotVelocity>1100</maxRotVelocity>
        <motorConstant>10.26e-06</motorConstant>
        <momentConstant>0.05</momentConstant>
        <commandSubTopic>/gazebo/command/motor_speed</commandSubTopic>
        <motorNumber>0</motorNumber>
        <rotorDragCoefficient>0.000175</rotorDragCoefficient>
        <rollingMomentCoefficient>1e-06</rollingMomentCoefficient>
        <motorSpeedPubTopic>/motor_speed/0</motorSpeedPubTopic>
        <rotorVelocitySlowdownSim>10</rotorVelocitySlowdownSim>
      </plugin>
      <plugin name='back_left_motor_model' filename='libgazebo_motor_model.so'>
        <robotNamespace/>
        <jointName>rotor_1_joint</jointName>
        <linkName>rotor_1</linkName>
        <turningDirection>ccw</turningDirection>
        <timeConstantUp>0.0125</timeConstantUp>
        <timeConstantDown>0.025</timeConstantDown>
        <maxRotVelocity>1100</maxRotVelocity>
        <motorConstant>10.26e-06</motorConstant>
        <momentConstant>0.05</momentConstant>
        <commandSubTopic>/gazebo/command/motor_speed</commandSubTopic>
        <motorNumber>1</motorNumber>
        <rotorDragCoefficient>0.000175</rotorDragCoefficient>
        <rollingMomentCoefficient>1e-06</rollingMomentCoefficient>
        <motorSpeedPubTopic>/motor_speed/1</motorSpeedPubTopic>
        <rotorVelocitySlowdownSim>10</rotorVelocitySlowdownSim>
      </plugin>
      <plugin name='front_left_motor_model' filename='libgazebo_motor_model.so'>
        <robotNamespace/>
        <jointName>rotor_2_joint</jointName>
        <linkName>rotor_2</linkName>
        <turningDirection>cw</turningDirection>
        <timeConstantUp>0.0125</timeConstantUp>
        <timeConstantDown>0.025</timeConstantDown>
        <maxRotVelocity>1100</maxRotVelocity>
        <motorConstant>10.26e-06</motorConstant>
        <momentConstant>0.05</momentConstant>
        <commandSubTopic>/gazebo/command/motor_speed</commandSubTopic>
        <motorNumber>2</motorNumber>
        <rotorDragCoefficient>0.000175</rotorDragCoefficient>
        <rollingMomentCoefficient>1e-06</rollingMomentCoefficient>
        <motorSpeedPubTopic>/motor_speed/2</motorSpeedPubTopic>
        <rotorVelocitySlowdownSim>10</rotorVelocitySlowdownSim>
      </plugin>
      <plugin name='back_right_motor_model' filename='libgazebo_motor_model.so'>
        <robotNamespace/>
        <jointName>rotor_3_joint</jointName>
        <linkName>rotor_3</linkName>
        <turningDirection>cw</turningDirection>
        <timeConstantUp>0.0125</timeConstantUp>
        <timeConstantDown>0.025</timeConstantDown>
        <maxRotVelocity>1100</maxRotVelocity>
        <motorConstant>10.26e-06</motorConstant>
        <momentConstant>0.05</momentConstant>
        <commandSubTopic>/gazebo/command/motor_speed</commandSubTopic>
        <motorNumber>3</motorNumber>
        <rotorDragCoefficient>0.000175</rotorDragCoefficient>
        <rollingMomentCoefficient>1e-06</rollingMomentCoefficient>
        <motorSpeedPubTopic>/motor_speed/3</motorSpeedPubTopic>
        <rotorVelocitySlowdownSim>10</rotorVelocitySlowdownSim>
      </plugin>
      <include>
        <uri>model://gps</uri>
        <pose>0.05 0 0.04 0 0 0</pose>
        <name>gps0</name>
      </include>
      <joint name='gps0_joint' type='fixed'>
        <child>gps0::link</child>
        <parent>base_link</parent>
      </joint>
      <plugin name='groundtruth_plugin' filename='libgazebo_groundtruth_plugin.so'>
        <robotNamespace/>
      </plugin>
      <plugin name='magnetometer_plugin' filename='libgazebo_magnetometer_plugin.so'>
        <robotNamespace/>
        <pubRate>100</pubRate>
        <noiseDensity>0.0004</noiseDensity>
        <randomWalk>6.4e-06</randomWalk>
        <biasCorrelationTime>600</biasCorrelationTime>
        <magTopic>/mag</magTopic>
      </plugin>
      <plugin name='barometer_plugin' filename='libgazebo_barometer_plugin.so'>
        <robotNamespace/>
        <pubRate>50</pubRate>
        <baroTopic>/baro</baroTopic>
        <baroDriftPaPerSec>0</baroDriftPaPerSec>
      </plugin>
      <plugin name='mavlink_interface' filename='libgazebo_mavlink_interface.so'>
        <robotNamespace/>
        <imuSubTopic>/imu</imuSubTopic>
        <magSubTopic>/mag</magSubTopic>
        <baroSubTopic>/baro</baroSubTopic>
        <mavlink_addr>INADDR_ANY</mavlink_addr>
        <mavlink_tcp_port>4560</mavlink_tcp_port>
        <mavlink_udp_port>14560</mavlink_udp_port>
        <serialEnabled>0</serialEnabled>
        <serialDevice>/dev/ttyACM0</serialDevice>
        <baudRate>921600</baudRate>
        <qgc_addr>INADDR_ANY</qgc_addr>
        <qgc_udp_port>14550</qgc_udp_port>
        <sdk_addr>INADDR_ANY</sdk_addr>
        <sdk_udp_port>14540</sdk_udp_port>
        <hil_mode>0</hil_mode>
        <hil_state_level>0</hil_state_level>
        <send_vision_estimation>0</send_vision_estimation>
        <send_odometry>1</send_odometry>
        <enable_lockstep>1</enable_lockstep>
        <use_tcp>1</use_tcp>
        <motorSpeedCommandPubTopic>/gazebo/command/motor_speed</motorSpeedCommandPubTopic>
        <control_channels>
          <channel name='rotor1'>
            <input_index>0</input_index>
            <input_offset>0</input_offset>
            <input_scaling>1000</input_scaling>
            <zero_position_disarmed>0</zero_position_disarmed>
            <zero_position_armed>100</zero_position_armed>
            <joint_control_type>velocity</joint_control_type>
          </channel>
          <channel name='rotor2'>
            <input_index>1</input_index>
            <input_offset>0</input_offset>
            <input_scaling>1000</input_scaling>
            <zero_position_disarmed>0</zero_position_disarmed>
            <zero_position_armed>100</zero_position_armed>
            <joint_control_type>velocity</joint_control_type>
          </channel>
          <channel name='rotor3'>
            <input_index>2</input_index>
            <input_offset>0</input_offset>
            <input_scaling>1000</input_scaling>
            <zero_position_disarmed>0</zero_position_disarmed>
            <zero_position_armed>100</zero_position_armed>
            <joint_control_type>velocity</joint_control_type>
          </channel>
          <channel name='rotor4'>
            <input_index>3</input_index>
            <input_offset>0</input_offset>
            <input_scaling>1000</input_scaling>
            <zero_position_disarmed>0</zero_position_disarmed>
            <zero_position_armed>100</zero_position_armed>
            <joint_control_type>velocity</joint_control_type>
          </channel>
          <channel name='rotor5'>
            <input_index>4</input_index>
            <input_offset>1</input_offset>
            <input_scaling>324.6</input_scaling>
            <zero_position_disarmed>0</zero_position_disarmed>
            <zero_position_armed>0</zero_position_armed>
            <joint_control_type>velocity</joint_control_type>
            <joint_control_pid>
              <p>0.1</p>
              <i>0</i>
              <d>0</d>
              <iMax>0.0</iMax>
              <iMin>0.0</iMin>
              <cmdMax>2</cmdMax>
              <cmdMin>-2</cmdMin>
            </joint_control_pid>
            <joint_name>zephyr_delta_wing::propeller_joint</joint_name>
          </channel>
          <channel name='rotor6'>
            <input_index>5</input_index>
            <input_offset>0</input_offset>
            <input_scaling>0.524</input_scaling>
            <zero_position_disarmed>0</zero_position_disarmed>
            <zero_position_armed>0</zero_position_armed>
            <joint_control_type>position</joint_control_type>
            <joint_name>zephyr_delta_wing::flap_left_joint</joint_name>
            <joint_control_pid>
              <p>10.0</p>
              <i>0</i>
              <d>0</d>
              <iMax>0</iMax>
              <iMin>0</iMin>
              <cmdMax>20</cmdMax>
              <cmdMin>-20</cmdMin>
            </joint_control_pid>
          </channel>
          <channel name='rotor7'>
            <input_index>6</input_index>
            <input_offset>0</input_offset>
            <input_scaling>0.524</input_scaling>
            <zero_position_disarmed>0</zero_position_disarmed>
            <zero_position_armed>0</zero_position_armed>
            <joint_control_type>position</joint_control_type>
            <joint_name>zephyr_delta_wing::flap_right_joint</joint_name>
            <joint_control_pid>
              <p>10.0</p>
              <i>0</i>
              <d>0</d>
              <iMax>0</iMax>
              <iMin>0</iMin>
              <cmdMax>20</cmdMax>
              <cmdMin>-20</cmdMin>
            </joint_control_pid>
          </channel>
          <channel name='rotor8'>
            <input_index>7</input_index>
            <input_offset>0</input_offset>
            <input_scaling>0.524</input_scaling>
            <zero_position_disarmed>0</zero_position_disarmed>
            <zero_position_armed>0</zero_position_armed>
            <joint_control_type>position</joint_control_type>
          </channel>
        </control_channels>
      </plugin>
      <static>0</static>
      <plugin name='rotors_gazebo_imu_plugin' filename='libgazebo_imu_plugin.so'>
        <robotNamespace/>
        <linkName>/imu_link</linkName>
        <imuTopic>/imu</imuTopic>
        <gyroscopeNoiseDensity>0.00018665</gyroscopeNoiseDensity>
        <gyroscopeRandomWalk>3.8785e-05</gyroscopeRandomWalk>
        <gyroscopeBiasCorrelationTime>1000.0</gyroscopeBiasCorrelationTime>
        <gyroscopeTurnOnBiasSigma>0.0087</gyroscopeTurnOnBiasSigma>
        <accelerometerNoiseDensity>0.00186</accelerometerNoiseDensity>
        <accelerometerRandomWalk>0.006</accelerometerRandomWalk>
        <accelerometerBiasCorrelationTime>300.0</accelerometerBiasCorrelationTime>
        <accelerometerTurnOnBiasSigma>0.196</accelerometerTurnOnBiasSigma>
      </plugin>
      <plugin filename="libgazebo_ros2_control.so" name="gazebo_ros2_control">
        <parameters>$(find gazebo_robot)/config/hyper_robot4_position.yaml</parameters>
      </plugin>
    </gazebo>
    <ros2_control name="GazeboSystem" type="system">
      <hardware>
        <plugin>gazebo_ros2_control/GazeboSystem</plugin>
      </hardware>
      <joint name="Joint0">
        <command_interface name="position">
          <param name="min">-1.5707</param>
          <param name="max">1.5707</param>
        </command_interface>
        <state_interface name="position"/>
        <state_interface name="velocity"/>
      </joint>
      <joint name="Joint1">
        <command_interface name="position">
          <param name="min">-1.5707</param>
          <param name="max">1.5707</param>
        </command_interface>
        <state_interface name="position"/>
        <state_interface name="velocity"/>
      </joint>
      <joint name="Joint2">
        <command_interface name="position">
          <param name="min">-1.5707</param>
          <param name="max">1.5707</param>
        </command_interface>
        <state_interface name="position"/>
        <state_interface name="velocity"/>
      </joint>
      <joint name="Joint3">
        <command_interface name="position">
          <param name="min">-1.5707</param>
          <param name="max">1.5707</param>
        </command_interface>
        <state_interface name="position"/>
        <state_interface name="velocity"/>
      </joint>
      <joint name="Joint4">
        <command_interface name="position">
          <param name="min">-1.5707</param>
          <param name="max">1.5707</param>
        </command_interface>
        <state_interface name="position"/>
        <state_interface name="velocity"/>
      </joint>
    </ros2_control>
</robot>
