<sdf version='1.7'>
  <model name='hyper_robot4'>
    <link name='base_link'>
      <inertial>
        <pose>-0.000803 -0.007314 -0.027846 0 -0 0</pose>
        <mass>1.4037</mass>
        <inertia>
          <ixx>0.0017764</ixx>
          <ixy>-3.447e-06</ixy>
          <ixz>2.1856e-07</ixz>
          <iyy>0.0019607</iyy>
          <iyz>2.7013e-07</iyz>
          <izz>0.0032525</izz>
        </inertia>
      </inertial>
      <collision name='base_link_collision'>
        <pose>0 0 -0.1 0 -0 0</pose>
        <geometry>
          <box>
            <size>0.6 0.6 0.2</size>
          </box>
        </geometry>
      </collision>
      <visual name='base_link_visual'>
        <pose>0 0 0 0 -0 0</pose>
        <geometry>
          <mesh>
            <scale>1 1 1</scale>
            <uri>model://hyper_robot4/meshes/base_link.STL</uri>
          </mesh>
        </geometry>
      </visual>
    </link>
    <joint name='Joint0' type='revolute'>
      <pose relative_to='base_link'>0.02 0 -0.18065 0 -0 0</pose>
      <parent>base_link</parent>
      <child>Link1</child>
      <axis>
        <xyz>0 0 1</xyz>
        <limit>
          <lower>-1.5707</lower>
          <upper>1.5707</upper>
          <effort>1</effort>
          <velocity>1</velocity>
        </limit>
        <dynamics>
          <damping>0.01</damping>
          <friction>0</friction>
          <spring_reference>0</spring_reference>
          <spring_stiffness>0</spring_stiffness>
        </dynamics>
      </axis>
    </joint>
    <link name='Link1'>
      <pose relative_to='Joint0'>0 0 0 0 -0 0</pose>
      <inertial>
        <pose>0.03091 3.5e-05 0.029993 0 -0 0</pose>
        <mass>0.11138</mass>
        <inertia>
          <ixx>2.6005e-05</ixx>
          <ixy>-2.14e-13</ixy>
          <ixz>2.8039e-07</ixz>
          <iyy>1.7177e-05</iyy>
          <iyz>3.7239e-08</iyz>
          <izz>1.71e-05</izz>
        </inertia>
      </inertial>
      <visual name='Link1_visual'>
        <pose>0 0 0 0 -0 0</pose>
        <geometry>
          <mesh>
            <scale>1 1 1</scale>
            <uri>model://hyper_robot4/meshes/Link1.STL</uri>
          </mesh>
        </geometry>
      </visual>
    </link>
    <joint name='Joint1' type='revolute'>
      <pose relative_to='Link1'>0.0465 0 0 1.5708 1.5708 0</pose>
      <parent>Link1</parent>
      <child>Link2</child>
      <axis>
        <xyz>0 0 1</xyz>
        <limit>
          <lower>-1.5707</lower>
          <upper>1.5707</upper>
          <effort>1</effort>
          <velocity>1</velocity>
        </limit>
        <dynamics>
          <damping>0.1</damping>
          <friction>0</friction>
          <spring_reference>0</spring_reference>
          <spring_stiffness>0</spring_stiffness>
        </dynamics>
      </axis>
    </joint>
    <link name='Link2'>
      <pose relative_to='Joint1'>0 0 0 0 -0 0</pose>
      <inertial>
        <pose>0.044669 -0 -8e-06 0 -0 0</pose>
        <mass>0.089477</mass>
        <inertia>
          <ixx>1.9359e-05</ixx>
          <ixy>3.3333e-19</ixy>
          <ixz>3.7239e-08</ixz>
          <iyy>2.6927e-05</iyy>
          <iyz>3.7967e-21</iyz>
          <izz>1.3371e-05</izz>
        </inertia>
      </inertial>
      <visual name='Link2_visual'>
        <pose>0 0 0 0 -0 0</pose>
        <geometry>
          <mesh>
            <scale>1 1 1</scale>
            <uri>model://hyper_robot4/meshes/Link2.STL</uri>
          </mesh>
        </geometry>
      </visual>
    </link>
    <joint name='Joint2' type='revolute'>
      <pose relative_to='Link2'>0.06365 0 0 0 0 -1.5708</pose>
      <parent>Link2</parent>
      <child>Link3</child>
      <axis>
        <xyz>0 0 -1</xyz>
        <limit>
          <lower>-1.5707</lower>
          <upper>1.5707</upper>
          <effort>1</effort>
          <velocity>1</velocity>
        </limit>
        <dynamics>
          <damping>0.01</damping>
          <friction>0</friction>
          <spring_reference>0</spring_reference>
          <spring_stiffness>0</spring_stiffness>
        </dynamics>
      </axis>
    </joint>
    <link name='Link3'>
      <pose relative_to='Joint2'>0 0 0 0 -0 0</pose>
      <inertial>
        <pose>-0.002764 0.053128 3.4e-05 0 -0 0</pose>
        <mass>0.09428</mass>
        <inertia>
          <ixx>2.1264e-05</ixx>
          <ixy>4.9299e-07</ixy>
          <ixz>3.2007e-18</ixz>
          <iyy>1.7761e-05</iyy>
          <iyz>-5.2408e-19</iyz>
          <izz>2.4231e-05</izz>
        </inertia>
      </inertial>
      <visual name='Link3_visual'>
        <pose>0 0 0 0 -0 0</pose>
        <geometry>
          <mesh>
            <scale>1 1 1</scale>
            <uri>model://hyper_robot4/meshes/Link3.STL</uri>
          </mesh>
        </geometry>
      </visual>
    </link>
    <joint name='Joint3' type='revolute'>
      <pose relative_to='Link3'>0.00965 0.13565 0 1.57079 -1.57079 3.14159</pose>
      <parent>Link3</parent>
      <child>Link4</child>
      <axis>
        <xyz>0 0 1</xyz>
        <limit>
          <lower>-1.5707</lower>
          <upper>1.5707</upper>
          <effort>1</effort>
          <velocity>1</velocity>
        </limit>
        <dynamics>
          <damping>0.01</damping>
          <friction>0</friction>
          <spring_reference>0</spring_reference>
          <spring_stiffness>0</spring_stiffness>
        </dynamics>
      </axis>
    </joint>
    <link name='Link4'>
      <pose relative_to='Joint3'>0 0 0 0 -0 0</pose>
      <inertial>
        <pose>0 0.003126 -0.024086 0 -0 0</pose>
        <mass>0.09428</mass>
        <inertia>
          <ixx>2.8558e-05</ixx>
          <ixy>-5.4321e-20</ixy>
          <ixz>1.1994e-18</ixz>
          <iyy>1.7996e-05</iyy>
          <iyz>4.1851e-07</iyz>
          <izz>1.6701e-05</izz>
        </inertia>
      </inertial>
      <visual name='Link4_visual'>
        <pose>0 0 0 0 -0 0</pose>
        <geometry>
          <mesh>
            <scale>1 1 1</scale>
            <uri>model://hyper_robot4/meshes/Link4.STL</uri>
          </mesh>
        </geometry>
      </visual>
    </link>
    <joint name='Joint4' type='revolute'>
      <pose relative_to='Link4'>0 0 0 1.5708 -0 0</pose>
      <parent>Link4</parent>
      <child>Link5</child>
      <axis>
        <xyz>0 0 1</xyz>
        <limit>
          <lower>-1.5707</lower>
          <upper>1.5707</upper>
          <effort>1</effort>
          <velocity>1</velocity>
        </limit>
        <dynamics>
          <damping>0.01</damping>
          <friction>0</friction>
          <spring_reference>0</spring_reference>
          <spring_stiffness>0</spring_stiffness>
        </dynamics>
      </axis>
    </joint>
    <link name='Link5'>
      <pose relative_to='Joint4'>0 0 0 0 -0 0</pose>
      <inertial>
        <pose>-0 0.057083 6.6e-05 0 -0 0</pose>
        <mass>0.0488669</mass>
        <inertia>
          <ixx>7.18439e-05</ixx>
          <ixy>2.90795e-11</ixy>
          <ixz>1.53411e-13</ixz>
          <iyy>8.24828e-06</iyy>
          <iyz>4.17585e-08</iyz>
          <izz>6.70449e-05</izz>
        </inertia>
      </inertial>
      <visual name='Link5_visual'>
        <pose>0 0 0 0 -0 0</pose>
        <geometry>
          <mesh>
            <scale>1 1 1</scale>
            <uri>model://hyper_robot4/meshes/Link5.STL</uri>
          </mesh>
        </geometry>
      </visual>
      <visual name='Link5_fixed_joint_lump__Link6_visual_1'>
        <pose>0 0.177385 0 -1.5708 0 0</pose>
        <geometry>
          <mesh>
            <scale>1 1 1</scale>
            <uri>model://hyper_robot4/meshes/Link6.STL</uri>
          </mesh>
        </geometry>
      </visual>
    </link>
    <joint name='rotor_0_joint' type='revolute'>
      <pose relative_to='base_link'>0.15778 -0.15778 0.022914 -1.5708 0 1.7863</pose>
      <parent>base_link</parent>
      <child>rotor_0</child>
      <axis>
        <xyz>0 1 0</xyz>
        <limit>
          <lower>-1e+16</lower>
          <upper>1e+16</upper>
        </limit>
        <dynamics>
          <spring_reference>0</spring_reference>
          <spring_stiffness>0</spring_stiffness>
        </dynamics>
      </axis>
    </joint>
    <link name='rotor_0'>
      <pose relative_to='rotor_0_joint'>0 0 0 0 -0 0</pose>
      <inertial>
        <pose>0 -0.004483 -0 0 -0 0</pose>
        <mass>0.022944</mass>
        <inertia>
          <ixx>8.117e-07</ixx>
          <ixy>-1.5304e-17</ixy>
          <ixz>2.5395e-06</ixz>
          <iyy>9.7213e-05</iyy>
          <iyz>2.8509e-18</iyz>
          <izz>9.6561e-05</izz>
        </inertia>
      </inertial>
      <visual name='rotor_0_visual'>
        <pose>0 0 0 0 -0 0</pose>
        <geometry>
          <mesh>
            <scale>1 1 1</scale>
            <uri>model://hyper_robot4/meshes/rotor0.STL</uri>
          </mesh>
        </geometry>
      </visual>
    </link>
    <joint name='rotor_1_joint' type='revolute'>
      <pose relative_to='base_link'>-0.15778 0.15778 0.022914 -1.5708 -0 1.7179</pose>
      <parent>base_link</parent>
      <child>rotor_1</child>
      <axis>
        <xyz>0 1 0</xyz>
        <limit>
          <lower>-1e+16</lower>
          <upper>1e+16</upper>
        </limit>
        <dynamics>
          <spring_reference>0</spring_reference>
          <spring_stiffness>0</spring_stiffness>
        </dynamics>
      </axis>
    </joint>
    <link name='rotor_1'>
      <pose relative_to='rotor_1_joint'>0 0 0 0 -0 0</pose>
      <inertial>
        <pose>-0 -0.004483 0 0 -0 0</pose>
        <mass>0.022944</mass>
        <inertia>
          <ixx>8.1171e-07</ixx>
          <ixy>4.1874e-14</ixy>
          <ixz>2.5395e-06</ixz>
          <iyy>9.7213e-05</iyy>
          <iyz>-1.6511e-14</iyz>
          <izz>9.6562e-05</izz>
        </inertia>
      </inertial>
      <visual name='rotor_1_visual'>
        <pose>0 0 0 0 -0 0</pose>
        <geometry>
          <mesh>
            <scale>1 1 1</scale>
            <uri>model://hyper_robot4/meshes/rotor1.STL</uri>
          </mesh>
        </geometry>
      </visual>
    </link>
    <joint name='rotor_2_joint' type='revolute'>
      <pose relative_to='base_link'>0.15778 0.15778 0.0245 1.5708 0 0.18169</pose>
      <parent>base_link</parent>
      <child>rotor_2</child>
      <axis>
        <xyz>0 1 0</xyz>
        <limit>
          <lower>-1e+16</lower>
          <upper>1e+16</upper>
        </limit>
        <dynamics>
          <spring_reference>0</spring_reference>
          <spring_stiffness>0</spring_stiffness>
        </dynamics>
      </axis>
    </joint>
    <link name='rotor_2'>
      <pose relative_to='rotor_2_joint'>0 0 0 0 -0 0</pose>
      <inertial>
        <pose>0 0.0061 0 0 -0 0</pose>
        <mass>0.022896</mass>
        <inertia>
          <ixx>8.0904e-07</ixx>
          <ixy>5.4318e-14</ixy>
          <ixz>-2.5351e-06</ixz>
          <iyy>9.711e-05</iyy>
          <iyz>2.2555e-14</iyz>
          <izz>9.646e-05</izz>
        </inertia>
      </inertial>
      <visual name='rotor_2_visual'>
        <pose>0 0 0 0 -0 0</pose>
        <geometry>
          <mesh>
            <scale>1 1 1</scale>
            <uri>model://hyper_robot4/meshes/rotor2.STL</uri>
          </mesh>
        </geometry>
      </visual>
    </link>
    <joint name='rotor_3_joint' type='revolute'>
      <pose relative_to='base_link'>-0.15778 -0.15778 0.02285 -1.5708 -0 -2.9802</pose>
      <parent>base_link</parent>
      <child>rotor_3</child>
      <axis>
        <xyz>0 1 0</xyz>
        <limit>
          <lower>-1e+16</lower>
          <upper>1e+16</upper>
        </limit>
        <dynamics>
          <spring_reference>0</spring_reference>
          <spring_stiffness>0</spring_stiffness>
        </dynamics>
      </axis>
    </joint>
    <link name='rotor_3'>
      <pose relative_to='rotor_3_joint'>0 0 0 0 -0 0</pose>
      <inertial>
        <pose>0 -0.00455 0 0 -0 0</pose>
        <mass>0.022896</mass>
        <inertia>
          <ixx>8.0904e-07</ixx>
          <ixy>6.176e-13</ixy>
          <ixz>-2.5351e-06</ixz>
          <iyy>9.7111e-05</iyy>
          <iyz>6.4653e-14</iyz>
          <izz>9.6461e-05</izz>
        </inertia>
      </inertial>
      <visual name='rotor_3_visual'>
        <pose>0 0 0 0 -0 0</pose>
        <geometry>
          <mesh>
            <scale>1 1 1</scale>
            <uri>model://hyper_robot4/meshes/rotor3.STL</uri>
          </mesh>
        </geometry>
      </visual>
    </link>
    <static>0</static>
    <plugin name='rosbag' filename='libgazebo_multirotor_base_plugin.so'>
      <robotNamespace/>
      <linkName>base_link</linkName>
      <rotorVelocitySlowdownSim>10</rotorVelocitySlowdownSim>
    </plugin>
    <plugin name='front_right_motor_model' filename='libgazebo_motor_model.so'>
      <robotNamespace/>
      <jointName>rotor_0_joint</jointName>
      <linkName>rotor_0</linkName>
      <turningDirection>ccw</turningDirection>
      <timeConstantUp>0.0125</timeConstantUp>
      <timeConstantDown>0.025</timeConstantDown>
      <maxRotVelocity>1100</maxRotVelocity>
      <motorConstant>5.84e-06</motorConstant>
      <momentConstant>0.06</momentConstant>
      <commandSubTopic>/gazebo/command/motor_speed</commandSubTopic>
      <motorNumber>0</motorNumber>
      <rotorDragCoefficient>0.000175</rotorDragCoefficient>
      <rollingMomentCoefficient>1e-06</rollingMomentCoefficient>
      <motorSpeedPubTopic>/motor_speed/0</motorSpeedPubTopic>
      <rotorVelocitySlowdownSim>10</rotorVelocitySlowdownSim>
    </plugin>
    <plugin name='back_left_motor_model' filename='libgazebo_motor_model.so'>
      <robotNamespace/>
      <jointName>rotor_1_joint</jointName>
      <linkName>rotor_1</linkName>
      <turningDirection>ccw</turningDirection>
      <timeConstantUp>0.0125</timeConstantUp>
      <timeConstantDown>0.025</timeConstantDown>
      <maxRotVelocity>1100</maxRotVelocity>
      <motorConstant>5.84e-06</motorConstant>
      <momentConstant>0.06</momentConstant>
      <commandSubTopic>/gazebo/command/motor_speed</commandSubTopic>
      <motorNumber>1</motorNumber>
      <rotorDragCoefficient>0.000175</rotorDragCoefficient>
      <rollingMomentCoefficient>1e-06</rollingMomentCoefficient>
      <motorSpeedPubTopic>/motor_speed/1</motorSpeedPubTopic>
      <rotorVelocitySlowdownSim>10</rotorVelocitySlowdownSim>
    </plugin>
    <plugin name='front_left_motor_model' filename='libgazebo_motor_model.so'>
      <robotNamespace/>
      <jointName>rotor_2_joint</jointName>
      <linkName>rotor_2</linkName>
      <turningDirection>cw</turningDirection>
      <timeConstantUp>0.0125</timeConstantUp>
      <timeConstantDown>0.025</timeConstantDown>
      <maxRotVelocity>1100</maxRotVelocity>
      <motorConstant>5.84e-06</motorConstant>
      <momentConstant>0.06</momentConstant>
      <commandSubTopic>/gazebo/command/motor_speed</commandSubTopic>
      <motorNumber>2</motorNumber>
      <rotorDragCoefficient>0.000175</rotorDragCoefficient>
      <rollingMomentCoefficient>1e-06</rollingMomentCoefficient>
      <motorSpeedPubTopic>/motor_speed/2</motorSpeedPubTopic>
      <rotorVelocitySlowdownSim>10</rotorVelocitySlowdownSim>
    </plugin>
    <plugin name='back_right_motor_model' filename='libgazebo_motor_model.so'>
      <robotNamespace/>
      <jointName>rotor_3_joint</jointName>
      <linkName>rotor_3</linkName>
      <turningDirection>cw</turningDirection>
      <timeConstantUp>0.0125</timeConstantUp>
      <timeConstantDown>0.025</timeConstantDown>
      <maxRotVelocity>1100</maxRotVelocity>
      <motorConstant>5.84e-06</motorConstant>
      <momentConstant>0.06</momentConstant>
      <commandSubTopic>/gazebo/command/motor_speed</commandSubTopic>
      <motorNumber>3</motorNumber>
      <rotorDragCoefficient>0.000175</rotorDragCoefficient>
      <rollingMomentCoefficient>1e-06</rollingMomentCoefficient>
      <motorSpeedPubTopic>/motor_speed/3</motorSpeedPubTopic>
      <rotorVelocitySlowdownSim>10</rotorVelocitySlowdownSim>
    </plugin>
    <frame name='gps0::__model__' attached_to='gps0::link'>
      <pose relative_to='__model__'>0.05 0 0.04 0 -0 0</pose>
    </frame>
    <link name='gps0::link'>
      <pose relative_to='gps0::__model__'>0 0 0 0 -0 0</pose>
      <inertial>
        <pose>0 0 0 0 -0 0</pose>
        <mass>0.015</mass>
        <inertia>
          <ixx>1e-05</ixx>
          <ixy>0</ixy>
          <ixz>0</ixz>
          <iyy>1e-05</iyy>
          <iyz>0</iyz>
          <izz>1e-05</izz>
        </inertia>
      </inertial>
      <visual name='visual'>
        <geometry>
          <cylinder>
            <radius>0.01</radius>
            <length>0.002</length>
          </cylinder>
        </geometry>
        <material>
          <script>
            <name>Gazebo/Black</name>
            <uri>__default__</uri>
          </script>
        </material>
      </visual>
      <sensor name='gps' type='gps'>
        <pose>0 0 0 0 -0 0</pose>
        <update_rate>5</update_rate>
        <always_on>1</always_on>
        <visualize>0</visualize>
        <plugin name='gps_plugin' filename='libgazebo_gps_plugin.so'>
          <robotNamespace/>
          <gpsNoise>1</gpsNoise>
          <gpsXYRandomWalk>2.0</gpsXYRandomWalk>
          <gpsZRandomWalk>4.0</gpsZRandomWalk>
          <gpsXYNoiseDensity>2.0e-4</gpsXYNoiseDensity>
          <gpsZNoiseDensity>4.0e-4</gpsZNoiseDensity>
          <gpsVXYNoiseDensity>0.2</gpsVXYNoiseDensity>
          <gpsVZNoiseDensity>0.4</gpsVZNoiseDensity>
        </plugin>
      </sensor>
    </link>
    <joint name='gps0_joint' type='fixed'>
      <child>gps0::link</child>
      <parent>base_link</parent>
    </joint>
    <plugin name='groundtruth_plugin' filename='libgazebo_groundtruth_plugin.so'>
      <robotNamespace/>
    </plugin>
    <plugin name='magnetometer_plugin' filename='libgazebo_magnetometer_plugin.so'>
      <robotNamespace/>
      <pubRate>100</pubRate>
      <noiseDensity>0.0004</noiseDensity>
      <randomWalk>6.4e-06</randomWalk>
      <biasCorrelationTime>600</biasCorrelationTime>
      <magTopic>/mag</magTopic>
    </plugin>
    <plugin name='barometer_plugin' filename='libgazebo_barometer_plugin.so'>
      <robotNamespace/>
      <pubRate>50</pubRate>
      <baroTopic>/baro</baroTopic>
      <baroDriftPaPerSec>0</baroDriftPaPerSec>
    </plugin>
    <plugin name='mavlink_interface' filename='libgazebo_mavlink_interface.so'>
      <robotNamespace/>
      <imuSubTopic>/imu</imuSubTopic>
      <magSubTopic>/mag</magSubTopic>
      <baroSubTopic>/baro</baroSubTopic>
      <mavlink_addr>INADDR_ANY</mavlink_addr>
      <mavlink_tcp_port>4560</mavlink_tcp_port>
      <mavlink_udp_port>14560</mavlink_udp_port>
      <serialEnabled>0</serialEnabled>
      <serialDevice>/dev/ttyACM0</serialDevice>
      <baudRate>921600</baudRate>
      <qgc_addr>INADDR_ANY</qgc_addr>
      <qgc_udp_port>14550</qgc_udp_port>
      <sdk_addr>INADDR_ANY</sdk_addr>
      <sdk_udp_port>14540</sdk_udp_port>
      <hil_mode>0</hil_mode>
      <hil_state_level>0</hil_state_level>
      <send_vision_estimation>0</send_vision_estimation>
      <send_odometry>1</send_odometry>
      <enable_lockstep>1</enable_lockstep>
      <use_tcp>1</use_tcp>
      <motorSpeedCommandPubTopic>/gazebo/command/motor_speed</motorSpeedCommandPubTopic>
      <control_channels>
        <channel name='rotor1'>
          <input_index>0</input_index>
          <input_offset>0</input_offset>
          <input_scaling>1000</input_scaling>
          <zero_position_disarmed>0</zero_position_disarmed>
          <zero_position_armed>100</zero_position_armed>
          <joint_control_type>velocity</joint_control_type>
        </channel>
        <channel name='rotor2'>
          <input_index>1</input_index>
          <input_offset>0</input_offset>
          <input_scaling>1000</input_scaling>
          <zero_position_disarmed>0</zero_position_disarmed>
          <zero_position_armed>100</zero_position_armed>
          <joint_control_type>velocity</joint_control_type>
        </channel>
        <channel name='rotor3'>
          <input_index>2</input_index>
          <input_offset>0</input_offset>
          <input_scaling>1000</input_scaling>
          <zero_position_disarmed>0</zero_position_disarmed>
          <zero_position_armed>100</zero_position_armed>
          <joint_control_type>velocity</joint_control_type>
        </channel>
        <channel name='rotor4'>
          <input_index>3</input_index>
          <input_offset>0</input_offset>
          <input_scaling>1000</input_scaling>
          <zero_position_disarmed>0</zero_position_disarmed>
          <zero_position_armed>100</zero_position_armed>
          <joint_control_type>velocity</joint_control_type>
        </channel>
        <channel name='rotor5'>
          <input_index>4</input_index>
          <input_offset>1</input_offset>
          <input_scaling>324.6</input_scaling>
          <zero_position_disarmed>0</zero_position_disarmed>
          <zero_position_armed>0</zero_position_armed>
          <joint_control_type>velocity</joint_control_type>
          <joint_control_pid>
            <p>0.1</p>
            <i>0</i>
            <d>0</d>
            <iMax>0.0</iMax>
            <iMin>0.0</iMin>
            <cmdMax>2</cmdMax>
            <cmdMin>-2</cmdMin>
          </joint_control_pid>
          <joint_name>zephyr_delta_wing::propeller_joint</joint_name>
        </channel>
        <channel name='rotor6'>
          <input_index>5</input_index>
          <input_offset>0</input_offset>
          <input_scaling>0.524</input_scaling>
          <zero_position_disarmed>0</zero_position_disarmed>
          <zero_position_armed>0</zero_position_armed>
          <joint_control_type>position</joint_control_type>
          <joint_name>zephyr_delta_wing::flap_left_joint</joint_name>
          <joint_control_pid>
            <p>10.0</p>
            <i>0</i>
            <d>0</d>
            <iMax>0</iMax>
            <iMin>0</iMin>
            <cmdMax>20</cmdMax>
            <cmdMin>-20</cmdMin>
          </joint_control_pid>
        </channel>
        <channel name='rotor7'>
          <input_index>6</input_index>
          <input_offset>0</input_offset>
          <input_scaling>0.524</input_scaling>
          <zero_position_disarmed>0</zero_position_disarmed>
          <zero_position_armed>0</zero_position_armed>
          <joint_control_type>position</joint_control_type>
          <joint_name>zephyr_delta_wing::flap_right_joint</joint_name>
          <joint_control_pid>
            <p>10.0</p>
            <i>0</i>
            <d>0</d>
            <iMax>0</iMax>
            <iMin>0</iMin>
            <cmdMax>20</cmdMax>
            <cmdMin>-20</cmdMin>
          </joint_control_pid>
        </channel>
        <channel name='rotor8'>
          <input_index>7</input_index>
          <input_offset>0</input_offset>
          <input_scaling>0.524</input_scaling>
          <zero_position_disarmed>0</zero_position_disarmed>
          <zero_position_armed>0</zero_position_armed>
          <joint_control_type>position</joint_control_type>
        </channel>
      </control_channels>
    </plugin>
    <plugin name='rotors_gazebo_imu_plugin' filename='libgazebo_imu_plugin.so'>
      <robotNamespace/>
      <linkName>/imu_link</linkName>
      <imuTopic>/imu</imuTopic>
      <gyroscopeNoiseDensity>0.00018665</gyroscopeNoiseDensity>
      <gyroscopeRandomWalk>3.8785e-05</gyroscopeRandomWalk>
      <gyroscopeBiasCorrelationTime>1000.0</gyroscopeBiasCorrelationTime>
      <gyroscopeTurnOnBiasSigma>0.0087</gyroscopeTurnOnBiasSigma>
      <accelerometerNoiseDensity>0.00186</accelerometerNoiseDensity>
      <accelerometerRandomWalk>0.006</accelerometerRandomWalk>
      <accelerometerBiasCorrelationTime>300.0</accelerometerBiasCorrelationTime>
      <accelerometerTurnOnBiasSigma>0.196</accelerometerTurnOnBiasSigma>
    </plugin>
    <plugin name='gazebo_ros2_control' filename='libgazebo_ros2_control.so'>
      <parameters>$(find gazebo_robot)/config/hyper_robot4_position.yaml</parameters>
    </plugin>
    <frame name='Joint5' attached_to='Link5'>
      <pose>0 0.177385 0 -1.5708 0 0</pose>
    </frame>
    <frame name='Link6' attached_to='Joint5'/>
  </model>
</sdf>
