<?xml version="1.0" encoding="utf-8"?>
<!-- This URDF was automatically created by SolidWorks to URDF Exporter! Originally created by Stephen Brawner (brawner@gmail.com) 
     Commit Version: 1.6.0-4-g7f85cfe  Build Version: 1.6.7995.38578
     For more information, please see http://wiki.ros.org/sw_urdf_exporter -->
<robot
  name="hyper_robot3">
  <link
    name="base_link">
    <inertial>
      <origin
        xyz="-0.000803320869880134 -0.00731373046963779 -0.0278463343314682"
        rpy="0 0 0" />
      <mass
        value="1.40368130340825" />
      <inertia
        ixx="0.00177636643734576"
        ixy="-3.44701652632128E-06"
        ixz="2.18559647330608E-07"
        iyy="0.00196072881316131"
        iyz="2.70132816572321E-07"
        izz="0.00325252818954745" />
    </inertial>
    <visual>
      <origin
        xyz="0 0 0"
        rpy="0 0 0" />
      <geometry>
        <mesh
          filename="package://hyper_robot3/meshes/base_link.STL" />
      </geometry>
      <material
        name="">
        <color
          rgba="1 1 1 1" />
      </material>
    </visual>
    <collision>
      <origin
        xyz="0 0 0"
        rpy="0 0 0" />
      <geometry>
        <mesh
          filename="package://hyper_robot3/meshes/base_link.STL" />
      </geometry>
    </collision>
  </link>
  <link
    name="Link1">
    <inertial>
      <origin
        xyz="0.0309099144247066 3.50891689570778E-05 0.0299927465319913"
        rpy="0 0 0" />
      <mass
        value="0.111376814962611" />
      <inertia
        ixx="2.60049834559125E-05"
        ixy="-2.14003618510062E-13"
        ixz="2.80394421762354E-07"
        iyy="1.71770039286567E-05"
        iyz="3.7239251940777E-08"
        izz="1.70999664027471E-05" />
    </inertial>
    <visual>
      <origin
        xyz="0 0 0"
        rpy="0 0 0" />
      <geometry>
        <mesh
          filename="package://hyper_robot3/meshes/Link1.STL" />
      </geometry>
      <material
        name="">
        <color
          rgba="0.698039215686274 0.698039215686274 0.698039215686274 1" />
      </material>
    </visual>
    <collision>
      <origin
        xyz="0 0 0"
        rpy="0 0 0" />
      <geometry>
        <mesh
          filename="package://hyper_robot3/meshes/Link1.STL" />
      </geometry>
    </collision>
  </link>
  <joint
    name="Joint0"
    type="continuous">
    <origin
      xyz="0.0200000000000002 0 -0.18065"
      rpy="0 0 0" />
    <parent
      link="base_link" />
    <child
      link="Link1" />
    <axis
      xyz="0 0 1" />
  </joint>
  <link
    name="Link2">
    <inertial>
      <origin
        xyz="0.0446686988012228 -1.38777878078145E-17 -7.86271712631015E-06"
        rpy="0 0 0" />
      <mass
        value="0.0894767571212673" />
      <inertia
        ixx="1.9359201211197E-05"
        ixy="2.09586739945917E-21"
        ixz="3.72393866049131E-08"
        iyy="2.69273005195101E-05"
        iyz="-1.68149818549231E-19"
        izz="1.33710484389844E-05" />
    </inertial>
    <visual>
      <origin
        xyz="0 0 0"
        rpy="0 0 0" />
      <geometry>
        <mesh
          filename="package://hyper_robot3/meshes/Link2.STL" />
      </geometry>
      <material
        name="">
        <color
          rgba="0.898039215686275 0.917647058823529 0.929411764705882 1" />
      </material>
    </visual>
    <collision>
      <origin
        xyz="0 0 0"
        rpy="0 0 0" />
      <geometry>
        <mesh
          filename="package://hyper_robot3/meshes/Link2.STL" />
      </geometry>
    </collision>
  </link>
  <joint
    name="Joint1"
    type="continuous">
    <origin
      xyz="0.0464999999999984 0 0"
      rpy="1.57079632679491 1.5707963267949 0" />
    <parent
      link="Link1" />
    <child
      link="Link2" />
    <axis
      xyz="0 0 1" />
  </joint>
  <link
    name="Link3">
    <inertial>
      <origin
        xyz="0.0105758143488388 0.0485952481655531 3.44790531098091E-05"
        rpy="0 0 0" />
      <mass
        value="0.0928720201733155" />
      <inertia
        ixx="2.08057028424611E-05"
        ixy="1.92062202926441E-07"
        ixz="6.09264988036772E-12"
        iyy="1.71776970275677E-05"
        iyz="-4.72448982282403E-13"
        izz="2.32825203729412E-05" />
    </inertial>
    <visual>
      <origin
        xyz="0 0 0"
        rpy="0 0 0" />
      <geometry>
        <mesh
          filename="package://hyper_robot3/meshes/Link3.STL" />
      </geometry>
      <material
        name="">
        <color
          rgba="0.898039215686275 0.917647058823529 0.929411764705882 1" />
      </material>
    </visual>
    <collision>
      <origin
        xyz="0 0 0"
        rpy="0 0 0" />
      <geometry>
        <mesh
          filename="package://hyper_robot3/meshes/Link3.STL" />
      </geometry>
    </collision>
  </link>
  <joint
    name="Joint2"
    type="continuous">
    <origin
      xyz="0.06365 0 0"
      rpy="0 0 -1.5707963267949" />
    <parent
      link="Link2" />
    <child
      link="Link3" />
    <axis
      xyz="0 0 0.999999999996974" />
  </joint>
  <link
    name="Link4">
    <inertial>
      <origin
        xyz="0.015686311339037 -4.36235910004175E-15 -0.0226772146559401"
        rpy="0 0 0" />
      <mass
        value="0.0928720201733156" />
      <inertia
        ixx="1.75376387218201E-05"
        ixy="-1.3802697202162E-20"
        ixz="1.17583429717184E-07"
        iyy="2.76101513790207E-05"
        iyz="-4.43669822143267E-20"
        izz="1.61181301421293E-05" />
    </inertial>
    <visual>
      <origin
        xyz="0 0 0"
        rpy="0 0 0" />
      <geometry>
        <mesh
          filename="package://hyper_robot3/meshes/Link4.STL" />
      </geometry>
      <material
        name="">
        <color
          rgba="0.898039215686275 0.917647058823529 0.929411764705882 1" />
      </material>
    </visual>
    <collision>
      <origin
        xyz="0 0 0"
        rpy="0 0 0" />
      <geometry>
        <mesh
          filename="package://hyper_robot3/meshes/Link4.STL" />
      </geometry>
    </collision>
  </link>
  <joint
    name="Joint3"
    type="continuous">
    <origin
      xyz="0.0256499999999205 0.12365 0"
      rpy="-1.57079632679475 0 0" />
    <parent
      link="Link3" />
    <child
      link="Link4" />
    <axis
      xyz="0 0 1" />
  </joint>
  <link
    name="Link5">
    <inertial>
      <origin
        xyz="-3.57147381639393E-14 0.0485952481655512 0.0151086908042478"
        rpy="0 0 0" />
      <mass
        value="0.0928720201733155" />
      <inertia
        ixx="2.76101513790206E-05"
        ixy="6.98496329375289E-18"
        ixz="1.1562062273571E-19"
        iyy="1.71776970275677E-05"
        iyz="-1.92062202926933E-07"
        izz="1.64780718363817E-05" />
    </inertial>
    <visual>
      <origin
        xyz="0 0 0"
        rpy="0 0 0" />
      <geometry>
        <mesh
          filename="package://hyper_robot3/meshes/Link5.STL" />
      </geometry>
      <material
        name="">
        <color
          rgba="0.898039215686275 0.917647058823529 0.929411764705882 1" />
      </material>
    </visual>
    <collision>
      <origin
        xyz="0 0 0"
        rpy="0 0 0" />
      <geometry>
        <mesh
          filename="package://hyper_robot3/meshes/Link5.STL" />
      </geometry>
    </collision>
  </link>
  <joint
    name="Joint4"
    type="continuous">
    <origin
      xyz="0.0416500000000051 0 0"
      rpy="1.57079632679479 0 -1.5707963267949" />
    <parent
      link="Link4" />
    <child
      link="Link5" />
    <axis
      xyz="0 0 1" />
  </joint>
  <link
    name="Link6">
    <inertial>
      <origin
        xyz="7.03662053644458E-15 0.0120248381799546 0.0572000217816001"
        rpy="0 0 0" />
      <mass
        value="0.0160210321477213" />
      <inertia
        ixx="6.1379895748013E-06"
        ixy="-3.87601853703786E-19"
        ixz="-4.75315674835079E-20"
        iyy="5.33421839756244E-06"
        iyz="-2.6389547841809E-21"
        izz="1.81035856873693E-06" />
    </inertial>
    <visual>
      <origin
        xyz="0 0 0"
        rpy="0 0 0" />
      <geometry>
        <mesh
          filename="package://hyper_robot3/meshes/Link6.STL" />
      </geometry>
      <material
        name="">
        <color
          rgba="0.898039215686275 0.917647058823529 0.929411764705882 1" />
      </material>
    </visual>
    <collision>
      <origin
        xyz="0 0 0"
        rpy="0 0 0" />
      <geometry>
        <mesh
          filename="package://hyper_robot3/meshes/Link6.STL" />
      </geometry>
    </collision>
  </link>
  <joint
    name="Joint5"
    type="continuous">
    <origin
      xyz="0 0 0"
      rpy="-1.57079632679479 0 0" />
    <parent
      link="Link5" />
    <child
      link="Link6" />
    <axis
      xyz="0 0 1" />
  </joint>
  <link
    name="end_effector">
    <inertial>
      <origin
        xyz="-1.7719E-08 -0.0022804 -0.076313"
        rpy="0 0 0" />
      <mass
        value="0.015815" />
      <inertia
        ixx="1.637E-05"
        ixy="-1.9417E-13"
        ixz="1.9043E-11"
        iyy="1.6416E-05"
        iyz="1.6425E-11"
        izz="3.701E-07" />
    </inertial>
    <visual>
      <origin
        xyz="0 0 0"
        rpy="0 0 0" />
      <geometry>
        <mesh
          filename="package://hyper_robot3/meshes/end_effector.STL" />
      </geometry>
      <material
        name="">
        <color
          rgba="0.69804 0.69804 0.69804 1" />
      </material>
    </visual>
    <collision>
      <origin
        xyz="0 0 0"
        rpy="0 0 0" />
      <geometry>
        <mesh
          filename="package://hyper_robot3/meshes/end_effector.STL" />
      </geometry>
    </collision>
  </link>
  <joint
    name="JointEnd"
    type="fixed">
    <origin
      xyz="0 0.043 0.144"
      rpy="0 0 0" />
    <parent
      link="Link6" />
    <child
      link="end_effector" />
    <axis
      xyz="0 0 1" />
  </joint>
</robot>