<?xml version="1.0" encoding="utf-8"?>
<!-- This URDF was automatically created by SolidWorks to URDF Exporter! Originally created by Stephen Brawner (brawner@gmail.com) 
     Commit Version: 1.6.0-4-g7f85cfe  Build Version: 1.6.7995.38578
     For more information, please see http://wiki.ros.org/sw_urdf_exporter -->
<robot
  name="hyper_robot4">
  <link
    name="base_link">
    <inertial>
      <origin
        xyz="-0.00080332 -0.0073137 -0.027846"
        rpy="0 0 0" />
      <mass
        value="1.4037" />
      <inertia
        ixx="0.0017764"
        ixy="-3.447E-06"
        ixz="2.1856E-07"
        iyy="0.0019607"
        iyz="2.7013E-07"
        izz="0.0032525" />
    </inertial>
    <visual>
      <origin
        xyz="0 0 0"
        rpy="0 0 0" />
      <geometry>
        <mesh
          filename="package://hyper_robot4/meshes/base_link.STL" />
      </geometry>
      <material
        name="">
        <color
          rgba="1 1 1 1" />
      </material>
    </visual>
    <collision>
      <origin
        xyz="0 0 0"
        rpy="0 0 0" />
      <geometry>
        <mesh
          filename="package://hyper_robot4/meshes/base_link.STL" />
      </geometry>
    </collision>
  </link>
  <link
    name="Link1">
    <inertial>
      <origin
        xyz="0.03091 3.5089E-05 0.029993"
        rpy="0 0 0" />
      <mass
        value="0.11138" />
      <inertia
        ixx="2.6005E-05"
        ixy="-2.14E-13"
        ixz="2.8039E-07"
        iyy="1.7177E-05"
        iyz="3.7239E-08"
        izz="1.71E-05" />
    </inertial>
    <visual>
      <origin
        xyz="0 0 0"
        rpy="0 0 0" />
      <geometry>
        <mesh
          filename="package://hyper_robot4/meshes/Link1.STL" />
      </geometry>
      <material
        name="">
        <color
          rgba="0.69804 0.69804 0.69804 1" />
      </material>
    </visual>
    <collision>
      <origin
        xyz="0 0 0"
        rpy="0 0 0" />
      <geometry>
        <mesh
          filename="package://hyper_robot4/meshes/Link1.STL" />
      </geometry>
    </collision>
  </link>
  <joint
    name="Joint0"
    type="revolute">
    <origin
      xyz="0.0200000000000003 0 -0.18065"
      rpy="0 0 0" />
    <parent
      link="base_link" />
    <child
      link="Link1" />
    <axis
      xyz="0 0 1" />
    <limit
      lower="-1.5707"
      upper="1.5707"
      effort="1"
      velocity="1" />
  </joint>
  <link
    name="Link2">
    <inertial>
      <origin
        xyz="0.044669 -3.9552E-15 -7.8627E-06"
        rpy="0 0 0" />
      <mass
        value="0.089477" />
      <inertia
        ixx="1.9359E-05"
        ixy="3.3333E-19"
        ixz="3.7239E-08"
        iyy="2.6927E-05"
        iyz="3.7967E-21"
        izz="1.3371E-05" />
    </inertial>
    <visual>
      <origin
        xyz="0 0 0"
        rpy="0 0 0" />
      <geometry>
        <mesh
          filename="package://hyper_robot4/meshes/Link2.STL" />
      </geometry>
      <material
        name="">
        <color
          rgba="0.89804 0.91765 0.92941 1" />
      </material>
    </visual>
    <collision>
      <origin
        xyz="0 0 0"
        rpy="0 0 0" />
      <geometry>
        <mesh
          filename="package://hyper_robot4/meshes/Link2.STL" />
      </geometry>
    </collision>
  </link>
  <joint
    name="Joint1"
    type="revolute">
    <origin
      xyz="0.0465 0 0"
      rpy="1.5707963267949 1.5707963267949 0" />
    <parent
      link="Link1" />
    <child
      link="Link2" />
    <axis
      xyz="0 0 1" />
    <limit
      lower="-1.5707"
      upper="1.5707"
      effort="1"
      velocity="1" />
  </joint>
  <link
    name="Link3">
    <inertial>
      <origin
        xyz="-0.0027639 0.053128 3.399E-05"
        rpy="0 0 0" />
      <mass
        value="0.09428" />
      <inertia
        ixx="2.1264E-05"
        ixy="4.9299E-07"
        ixz="3.2007E-18"
        iyy="1.7761E-05"
        iyz="-5.2408E-19"
        izz="2.4231E-05" />
    </inertial>
    <visual>
      <origin
        xyz="0 0 0"
        rpy="0 0 0" />
      <geometry>
        <mesh
          filename="package://hyper_robot4/meshes/Link3.STL" />
      </geometry>
      <material
        name="">
        <color
          rgba="0.89804 0.91765 0.92941 1" />
      </material>
    </visual>
    <collision>
      <origin
        xyz="0 0 0"
        rpy="0 0 0" />
      <geometry>
        <mesh
          filename="package://hyper_robot4/meshes/Link3.STL" />
      </geometry>
    </collision>
  </link>
  <joint
    name="Joint2"
    type="revolute">
    <origin
      xyz="0.0636500000000007 0 0"
      rpy="0 0 -1.5707963267949" />
    <parent
      link="Link2" />
    <child
      link="Link3" />
    <axis
      xyz="0 0 -1" />
    <limit
      lower="-1.5707"
      upper="1.5707"
      effort="1"
      velocity="1" />
  </joint>
  <link
    name="Link4">
    <inertial>
      <origin
        xyz="2.867E-14 0.0031256 -0.024086"
        rpy="0 0 0" />
      <mass
        value="0.09428" />
      <inertia
        ixx="2.8558E-05"
        ixy="-5.4321E-20"
        ixz="1.1994E-18"
        iyy="1.7996E-05"
        iyz="4.1851E-07"
        izz="1.6701E-05" />
    </inertial>
    <visual>
      <origin
        xyz="0 0 0"
        rpy="0 0 0" />
      <geometry>
        <mesh
          filename="package://hyper_robot4/meshes/Link4.STL" />
      </geometry>
      <material
        name="">
        <color
          rgba="0.89804 0.91765 0.92941 1" />
      </material>
    </visual>
    <collision>
      <origin
        xyz="0 0 0"
        rpy="0 0 0" />
      <geometry>
        <mesh
          filename="package://hyper_robot4/meshes/Link4.STL" />
      </geometry>
    </collision>
  </link>
  <joint
    name="Joint3"
    type="revolute">
    <origin
      xyz="0.00965 0.13565 0"
      rpy="-1.5708 -1.5708 0" />
    <parent
      link="Link3" />
    <child
      link="Link4" />
    <axis
      xyz="0 0 1" />
    <limit
      lower="-1.5707"
      upper="1.5707"
      effort="1"
      velocity="1" />
  </joint>
  <link
    name="Link5">
    <inertial>
      <origin
        xyz="-9.7548E-14 0.044044 8.1785E-05"
        rpy="0 0 0" />
      <mass
        value="0.039183" />
      <inertia
        ixx="2.725E-05"
        ixy="4.2357E-17"
        ixz="-4.6187E-18"
        iyy="8.1409E-06"
        iyz="3.294E-18"
        izz="2.2451E-05" />
    </inertial>
    <visual>
      <origin
        xyz="0 0 0"
        rpy="0 0 0" />
      <geometry>
        <mesh
          filename="package://hyper_robot4/meshes/Link5.STL" />
      </geometry>
      <material
        name="">
        <color
          rgba="0.89804 0.91765 0.92941 1" />
      </material>
    </visual>
    <collision>
      <origin
        xyz="0 0 0"
        rpy="0 0 0" />
      <geometry>
        <mesh
          filename="package://hyper_robot4/meshes/Link5.STL" />
      </geometry>
    </collision>
  </link>
  <joint
    name="Joint4"
    type="revolute">
    <origin
      xyz="0 0 0"
      rpy="1.5708 0 0" />
    <parent
      link="Link4" />
    <child
      link="Link5" />
    <axis
      xyz="0 0 1" />
    <limit
      lower="-1.5707"
      upper="1.5707"
      effort="1"
      velocity="1" />
  </joint>
  <link
    name="Link6">
    <inertial>
      <origin
        xyz="-2.6202E-08 -2.259E-08 -0.067545"
        rpy="0 0 0" />
      <mass
        value="0.0096839" />
      <inertia
        ixx="1.0979E-05"
        ixy="-1.7005E-13"
        ixz="1.5693E-11"
        iyy="1.0979E-05"
        iyz="1.3536E-11"
        izz="1.0733E-07" />
    </inertial>
    <visual>
      <origin
        xyz="0 0 0"
        rpy="0 0 0" />
      <geometry>
        <mesh
          filename="package://hyper_robot4/meshes/Link6.STL" />
      </geometry>
      <material
        name="">
        <color
          rgba="0.69804 0.69804 0.69804 1" />
      </material>
    </visual>
    <collision>
      <origin
        xyz="0 0 0"
        rpy="0 0 0" />
      <geometry>
        <mesh
          filename="package://hyper_robot4/meshes/Link6.STL" />
      </geometry>
    </collision>
  </link>
  <joint
    name="Joint5"
    type="revolute">
    <origin
      xyz="0 0.177384929880473 0"
      rpy="-1.57079632679532 0 0" />
    <parent
      link="Link5" />
    <child
      link="Link6" />
    <axis
      xyz="0 0 1" />
    <limit
      lower="-1.5707"
      upper="1.5707"
      effort="1"
      velocity="1" />
  </joint>
  <link name="freedom_roll" />
  <joint
    name="JointPenRoll"
    type="revolute">
    <parent
      link="Link6" />
    <child
      link="freedom_roll"/>
    <axis
      xyz="1 0 0"/>
    <limit
      lower="-0.7854"
      upper="0.7854"
      effort="1"
      velocity="1" />
  </joint>
  <link name="free_endeffector" />
  <joint
    name="JointPenPitch"
    type="revolute">
    <parent
      link="freedom_roll" />
    <child
      link="free_endeffector"/>
    <axis
      xyz="0 1 0"/>
    <limit
      lower="-0.7854"
      upper="0.7854"
      effort="1"
      velocity="1" />
  </joint>
</robot>